Workbook

Sheet Summary
A1: Column1 | B1: Column2 | C1: Column4 | D1: Column5 | E1: Profitability Dashboard | F1: Column7 | G1: Column8 | H1: Column9 | I1: Column10 | J1: Column11 | K1: Column12 | L1: Column13 | M1: Column14
A2: MASTERCARD FINANCIAL MODEL – EXECUTIVE SUMMARY | C2: Analyst | E2: Net Profit Margin (2020-2024) | F2: KPI Boxes
A3: (All figures in USD Millions unless stated otherwise) | C3: Item | D3: Value | E3: =Ratios!C16 -> 0.41899222 | F3: Revenue Growth
A4: Company Overview | B4: Description | C4: Market price | D4: =B36 -> 450 | E4: =Ratios!D28 -> 0.46001906 | F4: =B20 -> 0.16481028
A5: Company Name | B5: Mastercard Inc | C5: Target Price (12M) | D5: =B33 -> 389.90639 | E5: =Ratios!E28 -> 0.44655304 | F5: EBITDA Margin
A6: Industry | B6: Global Digital Payments | C6: Implied Downside: | D6: =B38 -> -0.13354135 | E6: =Ratios!F28 -> 0.44605148 | F6: 0.545
A7: Forecast Period | B7: 2025-2029 | E7: =Ratios!G28 -> 0.45705968 | F7: WACC
A8: Valuation Methods | B8: DCF,FCFE,FCFF,DDM,Relative Valuation | C8: Integrated Financial Model | D8: Revenue & EPS Growth Trend | F8: =WACC!B28 -> 0.094791294
A9: Key Players | B9: Visa, Mastercard, Paypal, American Express, Block inc, Global Payments | C9: Company: Mastercard Inc. | D9: Revenue (2020-2029 | E9: EPS (2020-2029) | F9: Intrinsic Value
A10: Downside is primarily driven by potential multiple compression as growth normalizes and valuation converges toward industry averages | C10: Analyst: Talla Varun Goud | D10: ='Profit Loss'!B4 -> 15301 | E10: ='Profit Loss'!B21 -> 6.4 | F10: =B37 -> 389.90639
A11: Financial Highlights | C11: Valuation Date: 2026 | D11: ='Profit Loss'!C4 -> 18884 | E11: ='Profit Loss'!C21 -> 8.79 | F11: Downside
A12: Metric | B12: Values | C12: Currency: USD Millions | D12: ='Profit Loss'!D4 -> 22237 | E12: ='Profit Loss'!D21 -> 10.26 | F12: =B38 -> -0.13354135
A13: Revenue Growth | B13: ='Valuation Dashboard'!B12 -> 0.11494394 | C13: DCF weighted higher due to intrinsic valuation reliability | D13: ='Profit Loss'!E4 -> 25098 | E13: ='Profit Loss'!E21 -> 11.86
A14: Net Profit Margin | B14: ='Profit Loss'!K20/'Profit Loss'!K4 -> 0.48585982 | D14: ='Profit Loss'!F4 -> 28167 | E14: ='Profit Loss'!F21 -> 13.91
A15: ROE | B15: ='Profit Loss'!K20/Balance_Sheet!K40 -> 1.235841 | C15: Recommendation Box | D15: ='Profit Loss'!G4 -> 31547.04 | E15: ='Profit Loss'!G21 -> 16.11343
A16: Free Cash Flow | B16: ='DCF Valuation'!G23 -> 111160.98 | C16: Recommendation: SELL | D16: ='Profit Loss'!H4 -> 35648.155 | E16: ='Profit Loss'!H21 -> 18.941557
C17: Target Price: $390 | D17: ='Profit Loss'!I4 -> 39925.934 | E17: ='Profit Loss'!I21 -> 21.862617
A18: Growth & Profitability | C18: Current Price: $450 | D18: ='Profit Loss'!J4 -> 44317.787 | E18: ='Profit Loss'!J21 -> 25.001704
A19: Key Insights | B19: Values | C19: Downside: -13.4% | D19: ='Profit Loss'!K4 -> 48749.565 | E19: ='Profit Loss'!K21 -> 28.32759
A20: Revenue CAGR | B20: ='CAGR Projections'!G4 -> 0.16481028 | C20: Key Reason: Overvaluation driven by high multiples despite strong fundamentals
A21: EPS CAGR | B21: ='CAGR Projections'!G7 -> 0.21419038 | C21: Key Investment Drivers | D21: Operating Margin (2020-2024) | E21: ROE (2020-2024) | F21: EBITDA (2020-2029)
A22: Average ROE | B22: =AVERAGE(Ratios!C13:G13) -> 1.4616261 | C22: Digital payment expansion | D22: =Ratios!C41 -> 0.52813542 | E22: =Ratios!C13 -> 0.98813194 | F22: ='Profit Loss'!B25 -> 8661
A23: Average Operating Margin | B23: =AVERAGE(Ratios!C41:G41) -> 0.54497449 | C23: Cross-border growth | D23: =Ratios!D41 -> 0.53389112 | E23: =Ratios!D13 -> 1.176622 | F23: ='Profit Loss'!C25 -> 10808
A24: High ROE driven by asset-light model and share buybacks | C24: High margins | D24: =Ratios!E41 -> 0.55151324 | E24: =Ratios!E13 -> 1.5623033 | F24: ='Profit Loss'!D25 -> 13014
C25: Network effects | D25: =Ratios!F41 -> 0.55813212 | E25: =Ratios!F13 -> 1.6050179 | F25: =Table1[[#This Row],[2023]] -> 14807
A26: Investment Summary & Recommendation | C26: Strong global payment network | D26: =Ratios!G41 -> 0.55320055 | E26: =Ratios!G13 -> 1.9760553 | F26: ='Profit Loss'!F25 -> 16479
A27: Method | B27: Implied Share Value ($) | D27: Final Investment Recommendation Chart | F27: ='Profit Loss'!G25 -> 18297.283
A28: DCF (Blended FCFF/FCFE) | B28: ='DCF Valuation'!B35 -> 386.11179 | C28: Valuation Methodology | D28: Method | E28: Final Investment Recommendation | F28: ='Profit Loss'!H25 -> 20996.763
A29: DCF (FCFF) | B29: ='Investment Recommendation'!D23 -> 118.33344 | C29: DCF and FCFF are weighted higher due to their | D29: Market Price | E29: 450 | F29: ='Profit Loss'!I25 -> 23676.079
A30: DCF (FCFE) | B30: ='Investment Recommendation'!B22 -> 335.44643 | C30: intrinsic valuation approach. | D30: DCF | E30: =B28 -> 386.11179 | F30: ='Profit Loss'!J25 -> 26457.719
A31: DDM | B31: DDM not applicable due to low dividend yield focus | C31: Relative valuation and DDM are used as | D31: FCFF | E31: =B29 -> 118.33344 | F31: ='Profit Loss'!K25 -> 29298.489
A32: Relative Valuation | B32: ='Investment Recommendation'!D21 -> 170.93903 | C32: supporting reference metrics. | D32: DDM | E32: =B31 -> DDM not applicable due to low dividend yield focus
A33: Valuation Weighting (Target Price) | B33: ='Investment Recommendation'!B25 -> 389.90639 | D33: Relative Valuation | E33: =B32 -> 170.93903
D34: Final Target Price | E34: =B33 -> 389.90639
A35: Final Investment Decision | B35: Values | C35: Free Cash Flow Trend
A36: Current Market Price | B36: ='DCF Valuation'!B36 -> 450 | C36: FCF | D36: Value
A37: Target Price | B37: =B33 -> 389.90639 | C37: 2025 | D37: ='DCF Valuation'!B23 -> 18784.948
A38: Upside/Downside | B38: =(B37-B36)/B36 -> -0.13354135 | C38: 2026 | D38: ='DCF Valuation'!C23 -> 19435.742
A39: Recommendation | B39: ='Investment Recommendation'!B45 -> SELL | C39: 2027 | D39: ='DCF Valuation'!D23 -> 21798.44
A40: Downside risk driven by valuation compression and sensitivity to WACC assumptions | C40: 2028 | D40: ='DCF Valuation'!E23 -> 24283.1
...

Sheet Executive Summary
A1: Financial Modelling & Valuation – Mastercard Inc. Executive Summary
A4: Business Overview
A5: Mastercard Inc. is a global payments technology company operating a global electronic payments network connecting consumers, financial institutions, merchants, and governments. The company earns revenue from transaction processing, cross-border payments, and value-added services. Its asset-light model enables strong scalability, high margins, and consistent growth driven by global digital payment adoption. Time Horizon: near-term (6–12 months) Key Competitors: Visa, PayPal, and emerging fintech disruptors
A11: Key Findings
A12: • Strong revenue and earnings growth • High operating margins and strong free cash flow • Industry leadership in profitability and efficiency • Stable financial position with manageable leverage • Beneficiary of global shift toward cashless transactions • Strong network effects creating high barriers to entry • Strong growth driven by cross-border transactions and digital payment adoption
A20: Fair Value Estimation
A21: Based on forecasted cash flows, growth assumptions, and WACC estimates, Mastercard’s intrinsic value is materially below the current market price, suggesting limited short-term upside despite strong long-term fundamentals. Sensitivity analysis indicates that valuation is moderately dependent on WACC and terminal growth assumptions.
A27: Investment Recommendation
A28: Mastercard demonstrates strong fundamentals, durable competitive advantages, and long-term growth potential within the global digital payments industry. However, the current market price exceeds intrinsic value estimates, resulting in limited upside and unfavorable risk-reward in the near term. Therefore, we recommend a SELL rating, implying ~11–12% downside from current levels.
A34: Numerical Valuation Box
A35: Current Market Price | C35: ='Investment Recommendation'!B42 -> 450 | E35: 🟢 Current Price
A36: Target Price | C36: ='Investment Recommendation'!B43 -> 389.90639 | E36: 🔴 Intrinsic Value
A37: Upside/Downside Potential | C37: ='Investment Recommendation'!B44 -> -0.13354135 | E37: ⚠️ Downside
A38: Recommendation | C38: ='Investment Recommendation'!B45 -> SELL
A40: Financial Highlights
A41: • Revenue CAGR | C41: =Summary!B20 -> 0.16481028
A42: • Operating Margin | C42: =Summary!B23 -> 0.54497449
A43: • ROE | C43: =Summary!B15 -> 1.235841
A44: • Projected Free Cash Flow | C44: =Summary!B16 -> 111160.98
A46: Key Risks
A47: • Regulatory pressure
A48: • Fintech competition
A49: • Global transaction slowdown
A50: • Cybersecurity or payment network disruption
A52: Conclusion: Mastercard remains a high-quality compounder, but current valuation limits near-term upside
A54: Valuation is primarily driven by terminal value, contributing ~65–70% of total enterprise value
A56: Re-entry recommended at $350–$370 range (or fair value band)
A58: Relative valuation (EV/EBITDA, P/E) also indicates a premium valuation, supporting the DCF conclusion.
A60: Investment Thesis
A61: Mastercard presents a strong long-term investment opportunity driven by:
A62: Global digital payments growth (shift from cash to cashless economy)
... A94: Based on DCF and relative valuation, Mastercard appears overvalued, with limited upside and potential downside risk under current assumptions.

Sheet Assumptions
A1: Assumptions | D1: Model Control | E1: Value
A2: 1. Revenue & Macroeconomic Assumptions | C2: Source-based reasoning (IMF, industry growth, etc.) | D2: Base Year | E2: 2024 | G2: Revenue Drivers | H2: 2025 | I2: 2026 | J2: 2027 | K2: 2028 | L2: 2029
A3: Assumption | B3: Value | C3: Basis | D3: Forecast Start | E3: 2025 | G3: Payment Volume Growth (%) | H3: 0.1 | I3: 0.11 | J3: 0.1 | K3: 0.09 | L3: 0.08
A4: Revenue Growth 2025E | B4: =H5 -> 0.12 | C4: Revenue growth is derived using a regression analysis between Mastercard’s historical revenue and GDP growth, indicating strong correlation with macroeconomic expansion and digital payment adoption. | D4: Forecast End | E4: 2029 | G4: Pricing Growth (%) | H4: 0.02 | I4: 0.02 | J4: 0.02 | K4: 0.02 | L4: 0.02
A5: Revenue Growth 2026E | B5: =I5 -> 0.13 | C5: Growth moderates as post-expansion effects stabilize, reflecting normalization after higher-than-trend growth in previous periods | D5: Currency | E5: USD Millions | G5: Total Revenue Growth (%) | H5: =H3+H4 -> 0.12 | I5: =I3+I4 -> 0.13 | J5: =J3+J4 -> 0.12 | K5: =K3+K4 -> 0.11 | L5: =L3+L4 -> 0.1
A6: Revenue Growth 2027E | B6: =J5 -> 0.12 | C6: Growth aligns with global digital payments industry trends, driven by steady transaction volume expansion and fintech adoption. | D6: Model Type: Integrated 3-Statement Financial Model | E6: Key Assumptions (Clean) | G6: Pricing growth is assumed to remain stable due to competitive pressures from Visa and emerging fintech players, which limit pricing expansion despite strong market positioning.
A7: Revenue Growth 2028E | B7: =K5 -> 0.11 | C7: As the company matures, growth gradually declines toward a sustainable long-term rate due to market saturation | D7: Valuation Approach: DCF + Relative Valuation | G7: Cost Driver | H7: 2025 | I7: 2026 | J7: 2027 | K7: 2028 | L7: 2029
A8: Revenue Growth 2029E | B8: =L5 -> 0.1 | C8: Growth approaches a steady-state level, reflecting stable economic expansion and a mature business lifecycle | D8: Forecast Horizon: 5 Years | E8: WACC: 9.48% | G8: Operating Expenses (% of Revenue) | H8: 0.25 | I8: 0.245 | J8: 0.24 | K8: 0.235 | L8: 0.23
A9: Terminal Growth (g) | B9: ='DCF Valuation'!B8 -> 0.03 | C9: Terminal growth reflects mature-stage growth aligned with inflation + GDP (~2–3%) | D9: Purpose: Investment Decision Analysis | E9: Terminal Growth: 3%
A10: Revenue Growth = Volume Growth + Pricing + Cross-border mix impact | C10: Key risk: deviation from GDP or cross-border slowdown can impact growth assumptions. | E10: EBITDA Margin: 55% → 57% | G10: The declining cost structure highlights operating leverage, where revenue growth outpaces cost growth, improving profitability over time
A11: 2. Income Statement Drivers
A12: Assumption | B12: Value | C12: Basis | D12: Revenue Drivers | E12: Investment View | G12: Margin Type | H12: Assumption | I12: Reason
C13: Operating Leverage | G13: EBITDA Margin | H13: Expanding from 55% → 57% | I13: Operating leverage
A14: Tax Rate | B14: 0.16 | C14: Based on the company’s historical effective tax rate, adjusted for global tax structure and geographic revenue mix | D14: Volume Growth: 8–10% | E14: Target Price: $373 | G14: Net Margin | H14: Stable | I14: Mature business
A15: Other Income | B15: -0.01 | C15: Assumes non-core income remains consistent with historical averages, reflecting minimal contribution to core operations. | D15: Pricing: ~2% | E15: Upside: Limited | G15: Margin expansion driven by scale in digital payments and cost efficiency
A16: EBIT Margin Trend | B16: Improving | C16: As revenue grows, fixed costs are spread over a larger base, improving margins due to operating leverage and high-margin digital business model. | D16: Cross-border: 1–2% | E16: Risk: Downside > Upside
A17: Opex Expansion Model | D17: Total Growth: ~11% | G17: Industry Linkage Section
A18: Year | B18: Opex % | C18: Operating Leverage & Automation Efficiency | G18: Factor | H18: Impact
A19: 2025 | B19: 0.45 | C19: 👉 Cost efficiency improves over time due to: | D19: Mastercard benefits from digital payment growth, but current valuation limits upside. | G19: Digital Payments Growth | H19: ↑ Revenue
A20: 2026 | B20: 0.44 | C20: Technology automation | G20: Fintech Competition | H20: ↓ Margins
A21: 2027 | B21: 0.435 | C21: Reduced marginal cost per transaction | G21: Regulation | H21: ↑ Costs
A22: 2028 | B22: 0.43 | C22: Scalable platform economics
A23: 2029 | B23: 0.425 | G23: Scenario | H23: Revenue Growth | I23: Margin | J23: WACC | K23: Terminal g | L23: Target Price
A24: 3.Working Capital Assumptions | G24: Bear | H24: -0.02 | I24: -0.01 | J24: 0.105 | K24: 0.025 | L24: $XXX
A25: Assumption | B25: Value | G25: Base | H25: 0 | I25: 0 | J25: 0.095 | K25: 0.03 | L25: $373
A26: Cash % Revenue | B26: 0.15 | C26: Maintained to ensure liquidity buffer and operational flexibility, consistent with historical treasury strategy. | G26: Bull | H26: 0.02 | I26: 0.01 | J26: 0.09 | K26: 0.035 | L26: $XXX
A27: Accounts Receivable % Revenue | B27: 0.0117 | C27: Low receivables due to fast settlement cycles in digital payment systems. | G27: Scenario analysis reflects sensitivity to key drivers including revenue growth, margins, discount rate, and terminal assumptions
A28: Settlement Assets % Revenue | B28: 0.134 | C28: Reflects funds in transit between institutions, a key characteristic of payment processing companies.
A29: Prepaid Assets % Revenue | B29: 0.08 | C29: Based on historical trends of advance payments and platform-related costs. | G29: Driver | H29: 2025 | I29: 2026 | J29: 2027 | K29: 2028 | L29: 2029
A30: Accrued Expenses % Revenue | B30: 0.369 | C30: High accruals due to transaction-related obligations and operational liabilities | G30: Payment Volume Growth | H30: 0.1 | I30: 0.11 | J30: 0.1 | K30: 0.09 | L30: 0.08
A31: 4. Asset & Investment Drivers | G31: Pricing / Take Rate | H31: 0.02 | I31: 0.02 | J31: 0.02 | K31: 0.02 | L31: 0.02
A32: Assumption | B32: Value | G32: Cross-border Mix | H32: 1–2% | I32: 1–2% | J32: 1–2% | K32: 1–2% | L32: 1–2%
A33: PPE Growth Rate | B33: 0.04 | C33: Moderate growth reflecting limited physical infrastructure needs (asset-light model) | G33: Total Revenue Growth | H33: 0.12 | I33: 0.13 | J33: 0.12 | K33: 0.11 | L33: 0.1
A34: Intangibles Growth Rate | B34: 0.03 | C34: Investment in technology, software, and intellectual property aligned with innovation strategy | G34: Revenue Growth = Payment Volume Growth + Pricing (Take Rate) + Cross-border Mix
A35: Depreciation % Revenue | B35: 0.055 | C35: Based on historical depreciation trends relative to asset base
A36: Capex % Revenue | B36: 0.07 | C36: Reflects continuous investment in:Technology Infrastructure Cyber Security Payment Network Expansion | G36: Driven by transaction volume, pricing power, and cross-border mix
A37: 5. Capital Allocation Assumptions
A38: Assumption | B38: Value
A39: Dividend Payout Ratio | B39: 0.3 | C39: Balanced policy to Reward Shareholders Retain Earnings for Growth | G39: As Mastercard is a mature, large-cap company, growth is expected to normalize over time.
A40: Share Buyback | B40: 0.02 | C40: Reflects consistent capital return strategy and confidence in future cash flows, also improving EPS | G40: This assumption reflects a stable, predictable cash flow profile without exceeding economic growth limits.
...

Sheet Assumption Notes
A1: Assumption Notes | J1: Assumption | K1: Value | L1: Explanation
A2: 1. Revenue Growth Assumptions | J2: Revenue Growth | K2: 0.1 | L2: Driven by digital payments growth
J3: Operating Margin | K3: 0.56 | L3: High-margin business model
A4: Base Case Growth Rate: 10% – 12% | J4: WACC | K4: 0.09 | L4: CAPM-based calculation
J5: Terminal Growth | K5: 0.03 | L5: GDP-linked growth
A6: Explanation:
J7: Sensitivity Insight
A8: Mastercard operates in the global digital payments industry, which is growing due to:
A9: Increasing shift from cash → digital payments | J9: “The model is most sensitive to changes in:
A10: E-commerce expansion
A11: Cross-border transactions recovery post-COVID | J11: Revenue growth rate
A12: Historical CAGR of Mastercard supports a double-digit growth range | J12: WACC
A13: Growth is slightly moderated vs past to reflect market maturity | J13: Terminal growth rate
J14: Even a 1% change in these variables significantly impacts valuation
A15: Bull Case: 14% – 16%
A17: Faster adoption of digital payments
A18: Expansion in emerging markets (India, Africa)
A20: Bear Case: 7% – 9%
A22: Economic slowdown
A23: Reduced consumer spending
A25: 2. Operating Margin Assumptions
A27: Base Case Margin: ~55% – 58%
A29: Explanation:
A31: Mastercard has a high-margin business model (asset-light)
A32: Margins are supported by:
A33: Strong pricing power
... A123: Industry positioning
A125: Scenario | B125: Growth | C125: Margin | D125: WACC
A126: Bull | B126: High | C126: Higher | D126: Lower
A127: Base | B127: Moderate | C127: Stable | D127: Normal
A128: Bear | B128: Low | C128: Declining | D128: Higher
A130: MACRO-ECONOMIC DRIVERS | J130: Driver | K130: Assumption | L130: Impact on Model
A131: 1. Global GDP Growth | J131: GDP Growth | K131: 0.03 | L131: Drives revenue growth
A132: Assumption: 2.5% – 3.5% | J132: Inflation | K132: 0.03 | L132: Impacts nominal revenue
J133: Interest Rate | K133: 0.05 | L133: Affects WACC
A134: Why it matters: | J134: Digital Payments Growth | K134: 0.12 | L134: Boosts revenue
J135: Consumer Spending | K135: Moderate | L135: Scenario driver
A136: Mastercard’s revenue is directly linked to consumer spending & economic activity | J136: Cross-border Transactions | K136: High | L136: Margin expansion
A137: Higher GDP → more transactions → higher payment volumes
A139: Model Link:
...

Sheet WACC
A1: WACC Calculation | F1: WACC = (E/V × Ke) + (D/V × Kd × (1 – Tax))
A2: A | B2: B | F2: WACC reflects Mastercard’s low leverage, strong credit profile, and market-based capital structure
A3: Cost of Equity (CAPM)
A4: Risk Free Rate | B4: =Assumptions!B43 -> 0.042 | F4: DCF value is driven by terminal value discounted at WACC
A5: Market Return | B5: =Assumptions!B45 -> 0.1 | F5: Low cost of debt reflects strong creditworthiness and stable cash flows
A6: Beta | B6: {=Table23[Value]} -> 1.0354654
A7: Cost of Equity | B7: =B4+B6*(B5-B4) -> 0.10205699 | F7: Valuation is highly sensitive to WACC, as a large portion of
A8: Pre-tax Cost of Debt | F8: DCF value is driven by terminal value discounted at WACC
A9: A | B9: B
A10: Pre-tax Cost of Debt | F10: Low WACC is primarily driven by high operating margins and
A11: Interest Expense | B11: =-'Profit Loss'!G15 -> 301.875 | F11: predictable cash flows rather than financial leverage
A12: Total Debt | B12: =Balance_Sheet!G27+Balance_Sheet!G24 -> 17250
A13: Cost of Debt | B13: =Assumptions!B50 -> 0.035 | F13: Given Mastercard’s asset-light model, equity investors bear most of the risk,
A14: A | B14: B | F14: which explains the high equity weight in WACC
A15: Capital Structure
A16: Market Price | B16: 450 | F16: Parameter | G16: Value | H16: Source | I16: Date | J16: Notes
A17: Shares Outstanding | B17: ='Profit Loss'!K24 -> 837.93458 | F17: Risk-Free Rate | G17: 0.042 | H17: RBI / US Treasury | I17: 46082 | J17: 10Y Govt Bond
A18: Market Cap | B18: =B16*B17 -> 377070.56 | F18: Market Return | G18: 0.09 | H18: S&P 500 Historical Avg | I18: 2025 | J18: Long-term avg
A19: Total Debt | B19: =B12 -> 17250 | F19: Beta | G19: 1.15 | H19: Bloomberg / Yahoo Finance | I19: 46082 | J19: 2Y weekly beta
A20: Enterprise Value | B20: =B18+B19 -> 394320.56 | F20: ERP | G20: 0.05 | H20: Damodaran Data | I20: 2025 | J20: US Equity Risk Premium
A21: Capital Weights | F21: Tax Rate | G21: 0.21 | H21: Company Filings | I21: 2024 | J21: Effective tax rate
A22: A | B22: B
A23: Equity Weight | B23: 0.9 | F23: Scenario | G23: Rf | H23: Beta | I23: Market Return
A24: Debt Weight | B24: 0.1 | F24: Base | G24: 0.04 | H24: 1.1 | I24: 0.09
A25: WACC | F25: Bull | G25: 0.035 | H25: 1 | I25: 0.1
A26: A | B26: B | F26: Bear | G26: 0.05 | H26: 1.3 | I26: 0.08
A27: Tax Rate | B27: =Assumptions!B14 -> 0.16
A28: WACC | B28: =(B23*B7)+(B24*B13*(1-B27)) -> 0.094791294
A30: Sources
A31: Risk-Free Rate = 4.2%
A32: Source: US 10Y Treasury Yield (Bloomberg / FRED)
A33: Date: [Latest available date]
A35: Market Risk Premium = 5.8%
A36: Source: Damodaran implied ERP (2025) / Historical US equity returns
A37: Rationale: Long-term US equity premium average
A39: Beta = 1.04
A40: Source: Regression vs S&P 500 (5-year monthly)
A42: Interpretation:
A43: Mastercard is slightly more volatile than the market due to
A44: exposure to global payment volumes and macro cycles
...

Sheet CAGR Projections
A1: CAGR Projections | N1: Item | O1: CAGR | P1: Insight
A2: Income Statement CAGR Projection | N2: Revenue | O2: 0.1648 | P2: Strong top-line growth
A3: Item | B3: 2020 | C3: 2021 | D3: 2022 | E3: 2023 | F3: 2024 | G3: CAGR | H3: 2025 | I3: 2026 | J3: 2027 | K3: 2028 | L3: 2029 | N3: Net Income | O3: 0.1904 | P3: Margin expansion
A4: Revenue | B4: =Table1[[#This Row],[2020]] -> 15301 | C4: =Table1[[#This Row],[2021]] -> 18884 | D4: =Table1[[#This Row],[2022]] -> 22237 | E4: =Table1[[#This Row],[2023]] -> 25098 | F4: =Table1[[#This Row],[2024]] -> 28167 | G4: =(Table51[[#This Row],[2024]] / Table51[[#This Row],[2020]])^(1/4)-1 -> 0.16481028 | H4: =F4*(1+$G4) -> 32809.211 | I4: =Table51[[#This Row],[2025]]*(1+Table51[[#This Row],[CAGR]]) -> 38216.506 | J4: =Table51[[#This Row],[2026]]*(1+Table51[[#This Row],[CAGR]]) -> 44514.98 | K4: =Table51[[#This Row],[2027]]*(1+Table51[[#This Row],[CAGR]]) -> 51851.506 | L4: =Table51[[#This Row],[2028]]*(1+Table51[[#This Row],[CAGR]]) -> 60397.167 | N4: FCF | O4: 0.1917 | P4: Strong cash generation
A5: Operating Income | B5: ='Profit Loss'!B11 -> 8081 | C5: ='Profit Loss'!C11 -> 10082 | D5: ='Profit Loss'!D11 -> 12264 | E5: ='Profit Loss'!E11 -> 14008 | F5: ='Profit Loss'!F11 -> 15582 | G5: =(Table51[[#This Row],[2024]] / Table51[[#This Row],[2020]])^(1/4)-1 -> 0.17839129 | H5: =F5*(1+$G5) -> 18361.693 | I5: =Table51[[#This Row],[2025]]*(1+Table51[[#This Row],[CAGR]]) -> 21637.259 | J5: =Table51[[#This Row],[2026]]*(1+Table51[[#This Row],[CAGR]]) -> 25497.158 | K5: =Table51[[#This Row],[2027]]*(1+Table51[[#This Row],[CAGR]]) -> 30045.629 | L5: =Table51[[#This Row],[2028]]*(1+Table51[[#This Row],[CAGR]]) -> 35405.507 | N5: Cash declining → Capital deployment (buybacks/dividends)
A6: Net Income | B6: ='Profit Loss'!B20 -> 6411 | C6: ='Profit Loss'!C20 -> 8687 | D6: ='Profit Loss'!D20 -> 9930 | E6: ='Profit Loss'!E20 -> 11195 | F6: ='Profit Loss'!F20 -> 12874 | G6: =(Table51[[#This Row],[2024]] / Table51[[#This Row],[2020]])^(1/4)-1 -> 0.190411 | H6: =F6*(1+$G6) -> 15325.351 | I6: =Table51[[#This Row],[2025]]*(1+Table51[[#This Row],[CAGR]]) -> 18243.467 | J6: =Table51[[#This Row],[2026]]*(1+Table51[[#This Row],[CAGR]]) -> 21717.223 | K6: =Table51[[#This Row],[2027]]*(1+Table51[[#This Row],[CAGR]]) -> 25852.422 | L6: =Table51[[#This Row],[2028]]*(1+Table51[[#This Row],[CAGR]]) -> 30775.007 | N6: 2020-2024 | O6: Historicals
A7: EPS | B7: ='Profit Loss'!B21 -> 6.4 | C7: ='Profit Loss'!C21 -> 8.79 | D7: ='Profit Loss'!D21 -> 10.26 | E7: ='Profit Loss'!E21 -> 11.86 | F7: ='Profit Loss'!F21 -> 13.91 | G7: =(Table51[[#This Row],[2024]] / Table51[[#This Row],[2020]])^(1/4)-1 -> 0.21419038 | H7: =F7*(1+$G7) -> 16.889388 | I7: =Table51[[#This Row],[2025]]*(1+Table51[[#This Row],[CAGR]]) -> 20.506933 | J7: =Table51[[#This Row],[2026]]*(1+Table51[[#This Row],[CAGR]]) -> 24.899321 | K7: =Table51[[#This Row],[2027]]*(1+Table51[[#This Row],[CAGR]]) -> 30.232516 | L7: =Table51[[#This Row],[2028]]*(1+Table51[[#This Row],[CAGR]]) -> 36.70803 | N7: 2025-2029 | O7: Projections
A9: Balance Sheet CAGR Projection
A10: Item | B10: 2020 | C10: 2021 | D10: 2022 | E10: 2023 | F10: 2024 | G10: CAGR | H10: 2025 | I10: 2026 | J10: 2027 | K10: 2028 | L10: 2029
A11: Total Assets | B11: =Balance_Sheet!B17 -> 33584 | C11: =Balance_Sheet!C17 -> 37669 | D11: =Balance_Sheet!D17 -> 38724 | E11: =Balance_Sheet!E17 -> 42448 | F11: =Balance_Sheet!F17 -> 48081 | G11: =(Table52[[#This Row],[2024]] / Table52[[#This Row],[2020]])^(1/4)-1 -> 0.093856288 | H11: =F11*(1+$G11) -> 52593.704 | I11: =Table52[[#This Row],[2025]]*(1+Table52[[#This Row],[CAGR]]) -> 57529.954 | J11: =Table52[[#This Row],[2026]]*(1+Table52[[#This Row],[CAGR]]) -> 62929.502 | K11: =Table52[[#This Row],[2027]]*(1+Table52[[#This Row],[CAGR]]) -> 68835.831 | L11: =Table52[[#This Row],[2028]]*(1+Table52[[#This Row],[CAGR]]) -> 75296.507
A12: Total Liabilities | B12: =Balance_Sheet!B30 -> 27067 | C12: =Balance_Sheet!C30 -> 30257 | D12: =Balance_Sheet!D30 -> 32347 | E12: =Balance_Sheet!E30 -> 35451 | F12: =Balance_Sheet!F30 -> 41566 | G12: =(Table52[[#This Row],[2024]] / Table52[[#This Row],[2020]])^(1/4)-1 -> 0.11320341 | H12: =F12*(1+$G12) -> 46271.413 | I12: =Table52[[#This Row],[2025]]*(1+Table52[[#This Row],[CAGR]]) -> 51509.495 | J12: =Table52[[#This Row],[2026]]*(1+Table52[[#This Row],[CAGR]]) -> 57340.545 | K12: =Table52[[#This Row],[2027]]*(1+Table52[[#This Row],[CAGR]]) -> 63831.69 | L12: =Table52[[#This Row],[2028]]*(1+Table52[[#This Row],[CAGR]]) -> 71057.655
A13: Shareholders Equity | B13: =Balance_Sheet!B40 -> 6488 | C13: =Balance_Sheet!C40 -> 7383 | D13: =Balance_Sheet!D40 -> 6356 | E13: =Balance_Sheet!E40 -> 6975 | F13: =Balance_Sheet!F40 -> 6515 | G13: =(Table52[[#This Row],[2024]] / Table52[[#This Row],[2020]])^(1/4)-1 -> 0.0010387626 | H13: =F13*(1+$G13) -> 6521.7675 | I13: =Table52[[#This Row],[2025]]*(1+Table52[[#This Row],[CAGR]]) -> 6528.5421 | J13: =Table52[[#This Row],[2026]]*(1+Table52[[#This Row],[CAGR]]) -> 6535.3237 | K13: =Table52[[#This Row],[2027]]*(1+Table52[[#This Row],[CAGR]]) -> 6542.1124 | L13: =Table52[[#This Row],[2028]]*(1+Table52[[#This Row],[CAGR]]) -> 6548.9081
A14: Cash & Cash Equivalents | B14: =Balance_Sheet!B4 -> 10113 | C14: =Balance_Sheet!C4 -> 7421 | D14: =Balance_Sheet!D4 -> 7008 | E14: =Balance_Sheet!E4 -> 8588 | F14: =Balance_Sheet!F4 -> 8442 | G14: =(Table52[[#This Row],[2024]] / Table52[[#This Row],[2020]])^(1/4)-1 -> -0.044146499 | H14: =F14*(1+$G14) -> 8069.3153 | I14: =Table52[[#This Row],[2025]]*(1+Table52[[#This Row],[CAGR]]) -> 7713.0832 | J14: =Table52[[#This Row],[2026]]*(1+Table52[[#This Row],[CAGR]]) -> 7372.5776 | K14: =Table52[[#This Row],[2027]]*(1+Table52[[#This Row],[CAGR]]) -> 7047.1041 | L14: =Table52[[#This Row],[2028]]*(1+Table52[[#This Row],[CAGR]]) -> 6735.9991
A16: Cash Flow Statement CAGR Projection
A17: Item | B17: 2020 | C17: 2021 | D17: 2022 | E17: 2023 | F17: 2024 | G17: CAGR | H17: 2025 | I17: 2026 | J17: 2027 | K17: 2028 | L17: 2029
A18: Operating Cash Flow | B18: ='Cash Flow'!B25 -> 7224 | C18: ='Cash Flow'!C25 -> 9463 | D18: ='Cash Flow'!D25 -> 11195 | E18: ='Cash Flow'!E25 -> 11980 | F18: ='Cash Flow'!F25 -> 14780 | G18: =(Table53[[#This Row],[2024]] / Table53[[#This Row],[2020]])^(1/4)-1 -> 0.19598071 | H18: =F18*(1+$G18) -> 17676.595 | I18: =Table53[[#This Row],[2025]]*(1+Table53[[#This Row],[CAGR]]) -> 21140.866 | J18: =Table53[[#This Row],[2026]]*(1+Table53[[#This Row],[CAGR]]) -> 25284.068 | K18: =Table53[[#This Row],[2027]]*(1+Table53[[#This Row],[CAGR]]) -> 30239.258 | L18: =Table53[[#This Row],[2028]]*(1+Table53[[#This Row],[CAGR]]) -> 36165.569
A19: Investing Cash Flow | B19: ='Cash Flow'!B39 -> -1879 | C19: ='Cash Flow'!C39 -> -5272 | D19: ='Cash Flow'!D39 -> -1470 | E19: ='Cash Flow'!E39 -> -1351 | F19: ='Cash Flow'!F39 -> -3402 | G19: =(Table53[[#This Row],[2024]] / Table53[[#This Row],[2020]])^(1/4)-1 -> 0.15998369 | H19: =AVERAGE(Table53[[#This Row],[2020]:[2024]]) -> -2674.8 | I19: =AVERAGE(Table53[[#This Row],[2020]:[2024]]) -> -2674.8 | J19: =AVERAGE(Table53[[#This Row],[2020]:[2024]]) -> -2674.8 | K19: =AVERAGE(Table53[[#This Row],[2020]:[2024]]) -> -2674.8 | L19: =AVERAGE(Table53[[#This Row],[2020]:[2024]]) -> -2674.8
A20: Financing Cash Flow | B20: ='Cash Flow'!B55 -> -2152 | C20: ='Cash Flow'!C55 -> -6555 | D20: ='Cash Flow'!D55 -> -10328 | E20: ='Cash Flow'!E55 -> -9488 | F20: ='Cash Flow'!F55 -> -10836 | G20: =(Table53[[#This Row],[2024]] / Table53[[#This Row],[2020]])^(1/4)-1 -> 0.4979823 | H20: =AVERAGE(Table53[[#This Row],[2020]:[2024]]) -> -7871.8 | I20: =AVERAGE(Table53[[#This Row],[2020]:[2024]]) -> -7871.8 | J20: =AVERAGE(Table53[[#This Row],[2020]:[2024]]) -> -7871.8 | K20: =AVERAGE(Table53[[#This Row],[2020]:[2024]]) -> -7871.8 | L20: =AVERAGE(Table53[[#This Row],[2020]:[2024]]) -> -7871.8
A21: Free Cash Flow | B21: ='Cash Flow'!B61 -> 7563 | C21: ='Cash Flow'!C61 -> 9870 | D21: ='Cash Flow'!D61 -> 11637 | E21: ='Cash Flow'!E61 -> 12351 | F21: ='Cash Flow'!F61 -> 15254 | G21: =(Table53[[#This Row],[2024]] / Table53[[#This Row],[2020]])^(1/4)-1 -> 0.19171501 | H21: =F21*(1+$G21) -> 18178.421 | I21: =Table53[[#This Row],[2025]]*(1+Table53[[#This Row],[CAGR]]) -> 21663.497 | J21: =Table53[[#This Row],[2026]]*(1+Table53[[#This Row],[CAGR]]) -> 25816.715 | K21: =Table53[[#This Row],[2027]]*(1+Table53[[#This Row],[CAGR]]) -> 30766.166 | L21: =Table53[[#This Row],[2028]]*(1+Table53[[#This Row],[CAGR]]) -> 36664.502
A23: Mastercard demonstrates strong double-digit growth across revenue, earnings, and cash flows, supported by operating leverage and a scalable business model.

Sheet Return Metrics
A1: Return Metrics | I1: Forecast CAGR Summary
A2: Metric | B2: 2024 | C2: 2025E | D2: 2026E | E2: 2027E | F2: 2028E | G2: 2029E | I2: Metrics | J2: 2024 | K2: 2029 | L2: CAGR
A3: ROE | B3: ='Profit Loss'!F20/Balance_Sheet!F40 -> 1.9760553 | C3: ='Profit Loss'!G20/Balance_Sheet!G40 -> 1.4481093 | D3: ='Profit Loss'!H20/Balance_Sheet!H40 -> 1.3672673 | E3: ='Profit Loss'!I20/Balance_Sheet!I40 -> 1.3114309 | F3: ='Profit Loss'!J20/Balance_Sheet!J40 -> 1.2688681 | G3: ='Profit Loss'!K20/Balance_Sheet!K40 -> 1.235841 | I3: Revenue | J3: ='Profit Loss'!F4 -> 28167 | K3: ='Profit Loss'!K4 -> 48749.565 | L3: =(K3/J3)^(1/4)-1 -> 0.14698447
A4: ROA | B4: ='Profit Loss'!F20/Balance_Sheet!F17 -> 0.26775649 | C4: ='Profit Loss'!G20/Balance_Sheet!G17 -> 0.27509523 | D4: ='Profit Loss'!H20/Balance_Sheet!H17 -> 0.29386809 | E4: ='Profit Loss'!I20/Balance_Sheet!I17 -> 0.30930307 | F4: ='Profit Loss'!J20/Balance_Sheet!J17 -> 0.32326605 | G4: ='Profit Loss'!K20/Balance_Sheet!K17 -> 0.33586271 | I4: EBITDA | J4: ='Profit Loss'!F25 -> 16479 | K4: ='Profit Loss'!K25 -> 29298.489 | L4: =(K4/J4)^(1/4)-1 -> 0.15472506
A5: FCF | B5: ='Cash Flow'!F61 -> 15254 | C5: ='Cash Flow'!G61 -> 18784.948 | D5: ='Cash Flow'!H61 -> 19435.742 | E5: ='Cash Flow'!I61 -> 21798.44 | F5: ='Cash Flow'!J61 -> 24283.1 | G5: ='Cash Flow'!K61 -> 26858.749 | I5: EPS | J5: ='Profit Loss'!F23 -> 13.89 | K5: ='Profit Loss'!K23 -> 28.266473 | L5: =(K5/J5)^(1/4)-1 -> 0.19437951
A6: EBIT | B6: ='Profit Loss'!F11 -> 15582 | C6: ='Profit Loss'!G11 -> 17350.872 | D6: ='Profit Loss'!H11 -> 19962.967 | E6: ='Profit Loss'!I11 -> 22558.153 | F6: ='Profit Loss'!J11 -> 25261.138 | G6: ='Profit Loss'!K11 -> 28031 | I6: FCF | J6: ='Cash Flow'!F61 -> 15254 | K6: =G5 -> 26858.749 | L6: =(K6/J6)^(1/4)-1 -> 0.15192846
A7: NOPAT | B7: ='Profit Loss'!F11*(1-Assumptions!B14) -> 13088.88 | C7: ='Profit Loss'!G11*(1-Assumptions!B14) -> 14574.732 | D7: ='Profit Loss'!H11*(1-Assumptions!B14) -> 16768.892 | E7: ='Profit Loss'!I11*(1-Assumptions!B14) -> 18948.848 | F7: ='Profit Loss'!J11*(1-Assumptions!B14) -> 21219.356 | G7: ='Profit Loss'!K11*(1-Assumptions!B14) -> 23546.04
A8: Invested Capital | B8: =(Balance_Sheet!F27+Balance_Sheet!F24)+Balance_Sheet!F40-Balance_Sheet!F4+'Cash Flow'!F25 -> 31079 | C8: =(Balance_Sheet!G27+Balance_Sheet!G24)+Balance_Sheet!G40-Balance_Sheet!G4+'Cash Flow'!G25 -> 36191.725 | D8: =(Balance_Sheet!H27+Balance_Sheet!H24)+Balance_Sheet!H40-Balance_Sheet!H4+'Cash Flow'!H25 -> 38245.39 | E8: =(Balance_Sheet!I27+Balance_Sheet!I24)+Balance_Sheet!I40-Balance_Sheet!I4+'Cash Flow'!I25 -> 42004.924 | F8: =(Balance_Sheet!J27+Balance_Sheet!J24)+Balance_Sheet!J40-Balance_Sheet!J4+'Cash Flow'!J25 -> 45981.971 | G8: =(Balance_Sheet!K27+Balance_Sheet!K24)+Balance_Sheet!K40-Balance_Sheet!K4+'Cash Flow'!K25 -> 50107.434
A9: Average Invested Capital (Beginning + Ending) / 2 | C9: =(B8+C8)/2 -> 33635.362 | D9: =(C8+D8)/2 -> 37218.558 | E9: =(D8+E8)/2 -> 40125.157 | F9: =(E8+F8)/2 -> 43993.448 | G9: =(F8+G8)/2 -> 48044.702
A10: ROIC = NOPAT / Average Invested Capital | B10: =B7/B8 -> 0.42114869 | C10: =C7/B8 -> 0.46895758 | D10: =D7/C8 -> 0.46333498 | E10: =E7/D8 -> 0.49545443 | F10: =F7/E8 -> 0.50516354 | G10: =G7/F8 -> 0.51207113
A11: WACC | B11: 0.0953 | C11: 0.0953 | D11: 0.0953 | E11: 0.0953 | F11: 0.0953 | G11: 0.0953
A12: NOTE
A13: NOPAT = EBIT × (1 − Tax Rate)
A14: ROIC = NOPAT / Average Invested Capital
A15: Invested Capital = Debt + Equity − Excess Cash
A17: Returns Chart
A18: Year | B18: ROIC | C18: ROE | D18: ROA
A19: 2024 | B19: =B10 -> 0.42114869 | C19: =B3 -> 1.9760553 | D19: =B4 -> 0.26775649
A20: 2025 | B20: =C10 -> 0.46895758 | C20: =C3 -> 1.4481093 | D20: =C4 -> 0.27509523
A21: 2026 | B21: =D10 -> 0.46333498 | C21: =D3 -> 1.3672673 | D21: =D4 -> 0.29386809
A22: 2027 | B22: =E10 -> 0.49545443 | C22: =E3 -> 1.3114309 | D22: =E4 -> 0.30930307
A23: 2028 | B23: =F10 -> 0.50516354 | C23: =F3 -> 1.2688681 | D23: =F4 -> 0.32326605
A24: 2029 | B24: =G10 -> 0.51207113 | C24: =G3 -> 1.235841 | D24: =G4 -> 0.33586271
A26: FCF Yield of Invested Capital | D26: Cost of Capital
A27: year | B27: Values | D27: year | E27: Values
A28: 2024 | B28: =B5/B8 -> 0.49081373 | D28: 2024 | E28: =B8*B11 -> 2961.8287
A29: 2025 | B29: =C5/C8 -> 0.51903987 | D29: 2025 | E29: =C8*B11 -> 3449.0714
A30: 2026 | B30: =D5/D8 -> 0.50818521 | D30: 2026 | E30: =D8*B11 -> 3644.7857
A31: 2027 | B31: =E5/E8 -> 0.51894964 | D31: 2027 | E31: =E8*B11 -> 4003.0693
A32: 2028 | B32: =F5/F8 -> 0.52810047 | D32: 2028 | E32: =F8*B11 -> 4382.0818
A33: 2029 | B33: =G5/G8 -> 0.53602323 | D33: 2029 | E33: =G8*B11 -> 4775.2384
A35: Economic Profit | D35: Value Spread
A36: year | B36: Values | D36: year | E36: Values
A37: 2024 | B37: =B7-E28 -> 10127.051 | D37: 2024 | E37: =B10-B11 -> 0.32584869
A38: 2025 | B38: =C7-E29 -> 11125.661 | D38: 2025 | E38: =C10-C11 -> 0.37365758
A39: 2026 | B39: =D7-E30 -> 13124.106 | D39: 2026 | E39: =D10-D11 -> 0.36803498
A40: 2027 | B40: =E7-E31 -> 14945.779 | D40: 2027 | E40: =E10-E11 -> 0.40015443
A41: 2028 | B41: =F7-E32 -> 16837.274 | D41: 2028 | E41: =F10-F11 -> 0.40986354
A42: 2029 | B42: =G7-E33 -> 18770.802 | D42: 2029 | E42: =G10-G11 -> 0.41677113
A44: Note: Declining ROIC due to reinvestment at scale and market maturity

Sheet Audit Checks
A1: Model Audit Checks | B1: =NOW() -> 46123.97
A2: Check | B2: Formula | C2: Status | D2: Description
A3: Balance Sheet | B3: =IF((Balance_Sheet!K36 - (Balance_Sheet!J36 + 'Profit Loss'!K20 + 'Cash Flow'!K42))<1, "OK", IF(ABS(Balance_Sheet!K36 - (Balance_Sheet!J36 + 'Profit Loss'!K20 + 'Cash Flow'!K42))<100, "WARNING", "ERROR")) -> OK | C3: =B3 -> OK | D3: Ensures Assets = Liabilities + Equity; validates overall financial balance
A4: Cash Flow | B4: =IF(ABS('Cash Flow'!K7-'Profit Loss'!K8)<1, "OK", IF(ABS('Cash Flow'!K7-'Profit Loss'!K8)<100, "WARNING", "ERROR")) -> OK | C4: =B4 -> OK | D4: Validates that ending cash equals beginning cash plus net cash flow
A5: Retained Earnings | B5: =IF((Balance_Sheet!K27-(Balance_Sheet!J27+'Cash Flow'!K43-'Cash Flow'!K48))<1, "OK", IF(ABS(Balance_Sheet!K27-(Balance_Sheet!J27+'Cash Flow'!K43-'Cash Flow'!K48))<100, "WARNING", "ERROR")) -> OK | C5: =B5 -> OK | D5: Checks retained earnings roll-forward: Opening RE + Net Income − Dividends
A6: Depreciation Link | B6: =IF(AND(ISNUMBER('Cash Flow'!K23),'Cash Flow'!K23<>0),"OK","ERROR") -> OK | C6: =B6 -> OK | D6: Ensures depreciation is consistently linked across all financial statements
A7: Debt Schedule | B7: =IF((Balance_Sheet!K27-(Balance_Sheet!J27+'Cash Flow'!K43-'Cash Flow'!K48))<1, "OK", IF(ABS(Balance_Sheet!K27-(Balance_Sheet!J27+'Cash Flow'!K43-'Cash Flow'!K48))<100, "WARNING", "ERROR")) -> OK | C7: =B7 -> OK | D7: Validates debt roll-forward: Opening Debt + Borrowings − Repayments
A8: Working Capital | B8: =IF(AND(ISNUMBER('Cash Flow'!K23),'Cash Flow'!K23<>0),"OK","ERROR") -> OK | C8: =B8 -> OK | D8: Ensures change in working capital is correctly calculated and linked
A9: FCFF Check | B9: =IF(ABS('DDM FCFF FCFE RelativeValuation'!H129 - ('DDM FCFF FCFE RelativeValuation'!B129*(1-'DDM FCFF FCFE RelativeValuation'!B116) + 'DDM FCFF FCFE RelativeValuation'!E129 - 'DDM FCFF FCFE RelativeValuation'!F129 - 'DDM FCFF FCFE RelativeValuation'!G129))<1, "OK", IF(ABS('DDM FCFF FCFE RelativeValuation'!H129 - ('DDM FCFF FCFE RelativeValuation'!B129*(1-'DDM FCFF FCFE RelativeValuation'!B116) + 'DDM FCFF FCFE RelativeValuation'!E129 - 'DDM FCFF FCFE RelativeValuation'!F129 - 'DDM FCFF FCFE RelativeValuation'!G129))<100, "WARNING","ERROR")) -> OK | C9: =B9 -> OK | D9: Validates FCFF using NOPAT + D&A − Capex − Change in Working Capital
A10: WACC Check | B10: =IF('DCF Valuation'!B13<=0, "ERROR", IF('DCF Valuation'!B13>1000000000, "WARNING", "OK")) -> OK | C10: =B10 -> OK | D10: Ensures appropriate discount rate based on capital structure
A11: Valuation Check | B11: =IF('Investment Recommendation'!B25<=0, "ERROR", IF('Investment Recommendation'!B25>10000, "WARNING", "OK")) -> OK | C11: =B11 -> OK | D11: Validates DCF outputs to ensure logical and positive valuation results
A12: Master Status | B12: =IF(COUNTIF(C:C,"ERROR")>0, "❌ MODEL HAS ERRORS", IF(COUNTIF(C:C,"WARNING")>0, "⚠️ MODEL HAS WARNINGS", "✅ MODEL IS CLEAN")) -> ✅ MODEL IS CLEAN | C12: =IF(COUNTIF(D:D,"ERROR")>0, "❌ MODEL HAS ERRORS", IF(COUNTIF(D:D,"WARNING")>0, "⚠️ MODEL HAS WARNINGS", "✅ MODEL IS CLEAN")) -> ✅ MODEL IS CLEAN | D12: Summarizes all audit checks to confirm overall model integrity
A13: Errors | B13: =COUNTIF(C:C,"ERROR") -> 0 | C13: =COUNTIF(D:D,"ERROR") -> 0 | D13: Counts critical issues that must be resolved before using the model
A14: Warnings | B14: =COUNTIF(C:C,"WARNING") -> 0 | C14: =COUNTIF(D:D,"WARNING") -> 0 | D14: Highlights non-critical issues or assumptions requiring review
A15: Dynamic Message | B15: =IF(COUNTIF(C:C,"ERROR")>0, "❌ Fix Errors", IF(COUNTIF(C:C,"WARNING")>0, "⚠️ Review Warnings", "✅ Model Ready for Use")) -> ✅ Model Ready for Use | C15: =IF(COUNTIF(D:D,"ERROR")>0, "❌ Fix Errors", IF(COUNTIF(D:D,"WARNING")>0, "⚠️ Review Warnings", "✅ Model Ready for Use")) -> ✅ Model Ready for Use | D15: Displays final model status: ready for use, review warnings, or fix errors
A17: Status Column:
A18: ✅ OK
A19: ⚠️ WARNING
A20: ❌ ERROR

Sheet Profit Loss
A1: Consolidated Statement of Operations - USD ($) shares in Millions, $ in Millions | B1: 2020 | C1: 2021 | D1: 2022 | E1: 2023 | F1: 2024 | G1: 2025E | H1: 2026E | I1: 2027E | J1: 2028E | K1: 2029E
A2: Mastercard Inc | M2: 2020-2024 | N2: Historicals
A3: Income Statement [Abstract] | M3: 2025-2029 | N3: Projections
A4: Net revenue | B4: 15301 | C4: 18884 | D4: 22237 | E4: 25098 | F4: 28167 | G4: =Table1[[#This Row],[2024]]*(1+Assumptions!H5) -> 31547.04 | H4: =Table1[[#This Row],[2025E]]*(1+Assumptions!I5) -> 35648.155 | I4: =Table1[[#This Row],[2026E]]*(1+Assumptions!J5) -> 39925.934 | J4: =Table1[[#This Row],[2027E]]*(1+Assumptions!K5) -> 44317.787 | K4: =Table1[[#This Row],[2028E]]*(1+Assumptions!L5) -> 48749.565
A5: Operating Expenses
A6: General and administrative | B6: 5910 | C6: 7087 | D6: 8078 | E6: 8927 | F6: 10193 | G6: =G4*10% -> 3154.704 | H6: =H4*10% -> 3564.8155 | I6: =I4*10% -> 3992.5934 | J6: =J4*10% -> 4431.7787 | K6: =K4*10% -> 4874.9565
A7: Advertising and marketing | B7: 657 | C7: 895 | D7: 789 | E7: 825 | F7: 815 | G7: =G4*3% -> 946.4112 | H7: =H4*3% -> 1069.4447 | I7: =I4*3% -> 1197.778 | J7: =J4*3% -> 1329.5336 | K7: =K4*3% -> 1462.487
A8: Depreciation and amortization | B8: 580 | C8: 726 | D8: 750 | E8: 799 | F8: 897 | G8: =G4*3% -> 946.4112 | H8: =H4*2.9% -> 1033.7965 | I8: =I4*2.8% -> 1117.9261 | J8: =J4*2.7% -> 1196.5802 | K8: =K4*2.6% -> 1267.4887
A9: Provision for litigation | B9: 73 | C9: 94 | D9: 356 | E9: 539 | F9: 680 | G9: =G4*2% -> 630.9408 | H9: =H4*2% -> 712.9631 | I9: =I4*2% -> 798.51868 | J9: =J4*2% -> 886.35573 | K9: =K4*2% -> 974.9913
A10: Total operating expenses | B10: 7220 | C10: 8802 | D10: 9973 | E10: 11090 | F10: 12585 | G10: =G4*Assumptions!B19 -> 14196.168 | H10: =H4*Assumptions!B20 -> 15685.188 | I10: =I4*Assumptions!B21 -> 17367.781 | J10: =J4*Assumptions!B22 -> 19056.648 | K10: =K4*Assumptions!B23 -> 20718.565
A11: Operating income (EBIT) | B11: 8081 | C11: 10082 | D11: 12264 | E11: 14008 | F11: 15582 | G11: =(G4-G10) -> 17350.872 | H11: =(H4-H10) -> 19962.967 | I11: =(I4-I10) -> 22558.153 | J11: =(J4-J10) -> 25261.138 | K11: =(K4-K10) -> 28031
A12: Other Income (Expense)
A13: Investment income | B13: 24 | C13: 11 | D13: 61 | E13: 274 | F13: 327 | G13: =Table1[[#This Row],[2024]]*1.04 -> 340.08 | H13: =Table1[[#This Row],[2025E]]*1.04 -> 353.6832 | I13: =Table1[[#This Row],[2026E]]*1.04 -> 367.83053 | J13: =Table1[[#This Row],[2027E]]*1.04 -> 382.54375 | K13: =Table1[[#This Row],[2028E]]*1.04 -> 397.8455
A14: Gains (losses) on equity investments, net | B14: 30 | C14: 645 | D14: -145 | E14: -61 | F14: -29 | G14: 0 | H14: 0 | I14: 0 | J14: 0 | K14: 0
A15: Interest expense | B15: -380 | C15: -431 | D15: -471 | E15: -575 | F15: -646 | G15: =G38 -> -301.875 | H15: =H38 -> -284.375 | I15: =I38 -> -266.875 | J15: =J38 -> -249.375 | K15: =K38 -> -231.875
A16: Other income (expense), net | B16: 5 | C16: 0 | D16: 23 | E16: -7 | F16: 20 | G16: 0 | H16: 0 | I16: 0 | J16: 0 | K16: 0
A17: Total other income (expense) | B17: -321 | C17: 225 | D17: -532 | E17: -369 | F17: -328 | G17: =G13+G14+G15+G16 -> 38.205 | H17: =H13+H14+H15+H16 -> 69.3082 | I17: =I13+I14+I15+I16 -> 100.95553 | J17: =J13+J14+J15+J16 -> 133.16875 | K17: =K13+K14+K15+K16 -> 165.9705
A18: Income before income taxes | B18: 7760 | C18: 10307 | D18: 11732 | E18: 13639 | F18: 15254 | G18: =G11+G17 -> 17389.077 | H18: =H11+H17 -> 20032.275 | I18: =I11+I17 -> 22659.108 | J18: =J11+J17 -> 25394.307 | K18: =K11+K17 -> 28196.97
A19: Income tax expense | B19: 1349 | C19: 1620 | D19: 1802 | E19: 2444 | F19: 2380 | G19: =G18*16% -> 2782.2523 | H19: =H18*16% -> 3205.164 | I19: =I18*16% -> 3625.4573 | J19: =J18*16% -> 4063.0891 | K19: =K18*16% -> 4511.5153
A20: Net Income | B20: 6411 | C20: 8687 | D20: 9930 | E20: 11195 | F20: 12874 | G20: =G18-G19 -> 14606.825 | H20: =H18-H19 -> 16827.111 | I20: =I18-I19 -> 19033.651 | J20: =J18-J19 -> 21331.218 | K20: =K18-K19 -> 23685.455
A21: Basic Earnings per Share | B21: 6.4 | C21: 8.79 | D21: 10.26 | E21: 11.86 | F21: 13.91 | G21: =G20/G22 -> 16.11343 | H21: =H20/H22 -> 18.941557 | I21: =I20/I22 -> 21.862617 | J21: =J20/J22 -> 25.001704 | K21: =K20/K22 -> 28.32759
A22: Basic weighted-average shares outstanding | B22: 1002 | C22: 988 | D22: 968 | E22: 944 | F22: 925 | G22: =Table1[[#This Row],[2024]]*(1-2%) -> 906.5 | H22: =Table1[[#This Row],[2025E]]*(1-2%) -> 888.37 | I22: =Table1[[#This Row],[2026E]]*(1-2%) -> 870.6026 | J22: =Table1[[#This Row],[2027E]]*(1-2%) -> 853.19055 | K22: =Table1[[#This Row],[2028E]]*(1-2%) -> 836.12674
A23: Diluted Earnings per Share | B23: 6.37 | C23: 8.76 | D23: 10.22 | E23: 11.83 | F23: 13.89 | G23: =G20/G24 -> 16.078666 | H23: =H20/H24 -> 18.900691 | I23: =I20/I24 -> 21.815448 | J23: =J20/J24 -> 24.947763 | K23: =K20/K24 -> 28.266473
A24: Diluted weighted-average shares outstanding | B24: 1006 | C24: 992 | D24: 971 | E24: 946 | F24: 927 | G24: =Table1[[#This Row],[2024]]*(1-Assumptions!B40) -> 908.46 | H24: =Table1[[#This Row],[2025E]]*(1-Assumptions!B40) -> 890.2908 | I24: =Table1[[#This Row],[2026E]]*(1-Assumptions!B40) -> 872.48498 | J24: =Table1[[#This Row],[2027E]]*(1-Assumptions!B40) -> 855.03528 | K24: =Table1[[#This Row],[2028E]]*(1-Assumptions!B40) -> 837.93458
A25: EBITDA | B25: =B11+B8 -> 8661 | C25: =C11+C8 -> 10808 | D25: =D11+D8 -> 13014 | E25: =E11+E8 -> 14807 | F25: =F11+F8 -> 16479 | G25: =G11+G8 -> 18297.283 | H25: =H11+H8 -> 20996.763 | I25: =I11+I8 -> 23676.079 | ... K25: =K11+K8 -> 29298.489
A26: Operating Margin | B26: =B11/B4 -> 0.52813542 | C26: =C11/C4 -> 0.53389112 | D26: =D11/D4 -> 0.55151324 | E26: =E11/E4 -> 0.55813212 | F26: =F11/F4 -> 0.55320055 | G26: =G11/G4 -> 0.55 | H26: =H11/H4 -> 0.56 | I26: =I11/I4 -> 0.565 | ... K26: =K11/K4 -> 0.575
A27: Net Margin | B27: =B20/B4 -> 0.41899222 | C27: =C20/C4 -> 0.46001906 | D27: =D20/D4 -> 0.44655304 | E27: =E20/E4 -> 0.44605148 | F27: =F20/F4 -> 0.45705968 | G27: =G20/G4 -> 0.46301728 | H27: =H20/H4 -> 0.47203315 | I27: =I20/I4 -> 0.476724 | ... K27: =K20/K4 -> 0.48585982
A28: Total | B28: =SUM(B4:B27) -> 63382.717 | C28: =SUM(C4:C27) -> 80440.544 | D28: =SUM(D4:D27) -> 91821.478 | E28: =SUM(E4:E27) -> 104547.69 | F28: =SUM(F4:F27) -> 117130.81 | G28: =SUM(G4:G27) -> 123772.56 | H28: =SUM(H4:H27) -> 140694.8 | I28: =SUM(I4:I27) -> 157942.7 | ... K28: =SUM(K4:K27) -> 193835.14
A29: Revenue growth is driven by increasing payment volumes and pricing power, while margin expansion reflects operating leverage in a scalable payment network. Share buybacks enhance EPS growth, reinforcing Mastercard’s strong earnings compounding profile.
A30: Interest expense increases in line with projected debt levels and higher interest rates
A31: Model assumes stable competitive positioning and continued global shift toward digital payments
A32: Mastercard benefits from strong network effects and an asset-light model, enabling high margins and predictable long-term cash flows
A34: Interest Expense | B34: 2020 | C34: 2021 | D34: 2022 | E34: 2023 | F34: 2024 | G34: 2025 | H34: 2026 | I34: 2027 | J34: 2028 | K34: 2029
A35: =Balance_Sheet!A27 -> Long-term debt | B35: =Balance_Sheet!B27 -> 12023 | C35: =Balance_Sheet!C27 -> 13109 | D35: =Balance_Sheet!D27 -> 13749 | E35: =Balance_Sheet!E27 -> 14344 | F35: =Balance_Sheet!F27 -> 17476 | G35: =Balance_Sheet!G27 -> 16500 | H35: =Balance_Sheet!H27 -> 15500 | ... K35: =Balance_Sheet!K27 -> 12500
A36: =Balance_Sheet!A24 -> Current portion of long-term debt | B36: =Balance_Sheet!B24 -> 649 | C36: =Balance_Sheet!C24 -> 792 | D36: =Balance_Sheet!D24 -> 274 | E36: =Balance_Sheet!E24 -> 1337 | F36: =Balance_Sheet!F24 -> 750 | G36: =Balance_Sheet!G24 -> 750 | H36: =Balance_Sheet!H24 -> 750 | ... K36: =Balance_Sheet!K24 -> 750
A37: Average Debt | B37: =(B35+B36)/2 -> 6336 | C37: =(C35+C36)/2 -> 6950.5 | D37: =(D35+D36)/2 -> 7011.5 | E37: =(E35+E36)/2 -> 7840.5 | F37: =(F35+F36)/2 -> 9113 | G37: =(G35+G36)/2 -> 8625 | H37: =(H35+H36)/2 -> 8125 | I37: =(I35+I36)/2 -> 7625 | ... K37: =(K35+K36)/2 -> 6625
A38: Interest Expense*Cost of Debt Assumption | B38: =-B37*Assumptions!B50 -> -221.76 | C38: =-C37*Assumptions!B50 -> -243.2675 | D38: =-D37*Assumptions!B50 -> -245.4025 | E38: =-E37*Assumptions!B50 -> -274.4175 | F38: =-F37*Assumptions!B50 -> -318.955 | G38: =-G37*Assumptions!B50 -> -301.875 | H38: =-H37*Assumptions!B50 -> -284.375 | I38: =-I37*Assumptions!B50 -> -266.875 | J38: =-J37*Assumptions!B50 -> -249.375 | K38: =-K37*Assumptions!B50 -> -231.875

Sheet Balance_Sheet
A1: Consolidated Balance Sheet - USD ($) $ in Millions | B1: 2020 | C1: 2021 | D1: 2022 | E1: 2023 | F1: 2024 | G1: 2025E | H1: 2026E | I1: 2027E | J1: 2028E | K1: 2029E
A2: Mastercard Inc | M2: 2020-2024 | N2: Historicals
A3: Assets | M3: 2025-2029 | N3: Projections
A4: Cash and cash equivalents | B4: 10113 | C4: 7421 | D4: 7008 | E4: 8588 | F4: 8442 | G4: ='Cash Flow'!G59 -> 9432.348 | H4: ='Cash Flow'!H59 -> 9224.8772 | I4: ='Cash Flow'!I59 -> 9008.4526 | J4: ='Cash Flow'!J59 -> 8786.1974 | K4: ='Cash Flow'!K59 -> 8561.8128
A5: Restricted Cash | B5: 586 | C5: 586 | D5: 589 | E5: 32 | F5: 492 | G5: 492 | H5: 492 | I5: 492 | J5: 492 | K5: 492
A6: Investments | B6: 483 | C6: 473 | D6: 400 | E6: 1845 | F6: 1874 | G6: 1874 | H6: 1874 | I6: 1874 | J6: 1874 | K6: 1874
A7: Accounts receivable | B7: 2646 | C7: 3006 | D7: 3425 | E7: 592 | F7: 330 | G7: ='Profit Loss'!G4*Assumptions!B27 -> 369.10037 | H7: ='Profit Loss'!H4*Assumptions!B27 -> 417.08342 | I7: ='Profit Loss'!I4*Assumptions!B27 -> 467.13343 | J7: ='Profit Loss'!J4*Assumptions!B27 -> 518.5181 | K7: ='Profit Loss'!K4*Assumptions!B27 -> 570.36991
A8: Settlement assets | B8: 1706 | C8: 1319 | D8: 1270 | E8: 4060 | F8: 3773 | G8: ='Profit Loss'!G4*Assumptions!B28 -> 4227.3034 | H8: ='Profit Loss'!H4*Assumptions!B28 -> 4776.8528 | I8: ='Profit Loss'!I4*Assumptions!B28 -> 5350.0751 | J8: ='Profit Loss'!J4*Assumptions!B28 -> 5938.5834 | K8: ='Profit Loss'!K4*Assumptions!B28 -> 6532.4417
A9: Restricted security deposits held for customers | B9: 1696 | C9: 1873 | D9: 1568 | E9: 1233 | F9: 1821 | G9: 1821 | H9: 1821 | I9: 1821 | J9: 1821 | K9: 1821
A10: Prepaid expenses and other current assets | B10: 1883 | C10: 2271 | D10: 2346 | E10: 2611 | F10: 2992 | G10: ='Profit Loss'!G4*Assumptions!B29 -> 2523.7632 | H10: ='Profit Loss'!H4*Assumptions!B29 -> 2851.8524 | I10: ='Profit Loss'!I4*Assumptions!B29 -> 3194.0747 | J10: ='Profit Loss'!J4*Assumptions!B29 -> 3545.4229 | K10: ='Profit Loss'!K4*Assumptions!B29 -> 3899.9652
A11: Total current assets | B11: =SUM(B4:B10) -> 19113 | C11: =SUM(C4:C10) -> 16949 | D11: =SUM(D4:D10) -> 16606 | E11: =SUM(E4:E10) -> 18961 | F11: =SUM(F4:F10) -> 19724 | G11: =SUM(G4:G10) -> 20739.515 | H11: =SUM(H4:H10) -> 21457.666 | I11: =SUM(I4:I10) -> 22206.736 | ... K11: =SUM(K4:K10) -> 23751.59
A12: Property, equipment and right-of-use assets, net | B12: 1902 | C12: 1907 | D12: 2006 | E12: 2061 | F12: 2138 | G12: =Table2[[#This Row],[2024]]*(1+4%) -> 2223.52 | H12: =Table2[[#This Row],[2025E]]*(1+4%) -> 2312.4608 | I12: =Table2[[#This Row],[2026E]]*(1+4%) -> 2404.9592 | J12: =Table2[[#This Row],[2027E]]*(1+4%) -> 2501.1576 | K12: =Table2[[#This Row],[2028E]]*(1+4%) -> 2601.2039
A13: Deferred income taxes | B13: 491 | C13: 486 | D13: 1151 | E13: 1355 | F13: 1614 | G13: 1614 | H13: 1614 | I13: 1614 | J13: 1614 | K13: 1614
A14: Goodwill | B14: 4960 | C14: 7662 | D14: 7522 | E14: 7660 | F14: 9193 | G14: 9193 | H14: 9193 | I14: 9193 | J14: 9193 | K14: 9193
A15: Other intangible assets, net | B15: 1753 | C15: 3671 | D15: 3859 | E15: 4086 | F15: 5453 | G15: =Table2[[#This Row],[2024]]*(1+3%) -> 5616.59 | H15: =Table2[[#This Row],[2025E]]*(1+3%) -> 5785.0877 | I15: =Table2[[#This Row],[2026E]]*(1+3%) -> 5958.6403 | J15: =Table2[[#This Row],[2027E]]*(1+3%) -> 6137.3995 | K15: =Table2[[#This Row],[2028E]]*(1+3%) -> 6321.5215
A16: Other assets | B16: 5365 | C16: 6994 | D16: 7580 | E16: 8325 | F16: 9959 | G16: ='Profit Loss'!G4*Assumptions!H5 -> 3785.6448 | H16: ='Profit Loss'!H4*Assumptions!I5 -> 4634.2602 | I16: ='Profit Loss'!I4*Assumptions!J5 -> 4791.1121 | J16: ='Profit Loss'!J4*Assumptions!K5 -> 4874.9565 | K16: ='Profit Loss'!K4*Assumptions!L5 -> 4874.9565
A17: Total Assets | B17: 33584 | C17: 37669 | D17: 38724 | E17: 42448 | F17: 48081 | G17: =G30+G40 -> 53097.339 | H17: =H30+H40 -> 57260.762 | I17: =I30+I40 -> 61537.22 | J17: =J30+J40 -> 65986.57 | K17: =K30+K40 -> 70521.242
A18: Liabilities, Redeemable Non-controlling Interests and Equity
A19: Accounts payable | B19: 527 | C19: 738 | D19: 926 | E19: 834 | F19: 929 | G19: ='Profit Loss'!G4*3.3% -> 1041.0523 | H19: ='Profit Loss'!H4*3.3% -> 1176.3891 | I19: ='Profit Loss'!I4*3.3% -> 1317.5558 | J19: ='Profit Loss'!J4*3.3% -> 1462.487 | K19: ='Profit Loss'!K4*3.3% -> 1608.7357
A20: Settlement obligations | B20: 1475 | C20: 913 | D20: 1111 | E20: 1399 | F20: 2316 | G20: ='Profit Loss'!G4*8.2% -> 2586.8573 | H20: ='Profit Loss'!H4*8.2% -> 2923.1487 | I20: ='Profit Loss'!I4*8.2% -> 3273.9266 | J20: ='Profit Loss'!J4*8.2% -> 3634.0585 | K20: ='Profit Loss'!K4*8.2% -> 3997.4643
A21: Restricted security deposits held for customers | B21: 1696 | C21: 1873 | D21: 1568 | E21: 1845 | F21: 1874 | G21: 1874 | H21: 1874 | I21: 1874 | J21: 1874 | K21: 1874
A22: Accrued litigation | B22: 842 | C22: 840 | D22: 1094 | E22: 723 | F22: 930 | G22: 930 | H22: 930 | I22: 930 | J22: 930 | K22: 930
A23: Accrued expenses | B23: 5430 | C23: 6642 | D23: 7801 | E23: 8517 | F23: 10393 | G23: ='Profit Loss'!G4*36.9% -> 11640.858 | H23: ='Profit Loss'!H4*36.9% -> 13154.169 | I23: ='Profit Loss'!I4*36.9% -> 14732.67 | J23: ='Profit Loss'!J4*36.9% -> 16353.263 | K23: ='Profit Loss'!K4*36.9% -> 17988.59
A24: Current portion of long-term debt | B24: 649 | C24: 792 | D24: 274 | E24: 1337 | F24: 750 | G24: 750 | H24: 750 | I24: 750 | J24: 750 | K24: 750
A25: Other current liabilities | B25: 1228 | C25: 1364 | D25: 1397 | E25: 1609 | F25: 2028 | G25: ='Profit Loss'!G4*7.2% -> 2271.3869 | H25: ='Profit Loss'!H4*7.2% -> 2566.6672 | I25: ='Profit Loss'!I4*7.2% -> 2874.6672 | J25: ='Profit Loss'!J4*7.2% -> 3190.8806 | K25: ='Profit Loss'!K4*7.2% -> 3509.9687
A26: Total current liabilities | B26: 11847 | C26: 13162 | D26: 14171 | E26: 16264 | F26: 19220 | G26: =SUM(G19:G25) -> 21094.154 | H26: =SUM(H19:H25) -> 23374.374 | I26: =SUM(I19:I25) -> 25752.819 | J26: =SUM(J19:J25) -> 28194.689 | K26: =SUM(K19:K25) -> 30658.758
A27: Long-term debt | B27: 12023 | C27: 13109 | D27: 13749 | E27: 14344 | F27: 17476 | G27: 16500 | H27: 15500 | I27: 14500 | J27: 13500 | K27: 12500
A28: Deferred income taxes | B28: 86 | C28: 395 | D28: 393 | E28: 369 | F28: 317 | G28: 317 | H28: 317 | I28: 317 | J28: 317 | K28: 317
A29: Other liabilities | B29: 3111 | C29: 3591 | D29: 4034 | E29: 4474 | F29: 4553 | G29: =Table2[[#This Row],[2024]]*(1+Assumptions!B4) -> 5099.36 | H29: =Table2[[#This Row],[2025E]]*(1+Assumptions!B5) -> 5762.2768 | I29: =Table2[[#This Row],[2026E]]*(1+Assumptions!B6) -> 6453.75 | J29: =Table2[[#This Row],[2027E]]*(1+Assumptions!B7) -> 7163.6625 | K29: =Table2[[#This Row],[2028E]]*(1+Assumptions!B8) -> 7880.0288
A30: Total Liabilities | B30: 27067 | C30: 30257 | D30: 32347 | E30: 35451 | F30: 41566 | G30: =G26+G27+G28+G29 -> 43010.514 | H30: =H26+H27+H28+H29 -> 44953.651 | I30: =I26+I27+I28+I29 -> 47023.569 | J30: =J26+J27+J28+J29 -> 49175.352 | K30: =K26+K27+K28+K29 -> 51355.787
A31: Commitments and Contingencies
A32: Redeemable non-controlling interests | B32: 29 | C32: 29 | D32: 21 | E32: 22 | F32: 0 | G32: 0 | H32: 0 | I32: 0 | J32: 0 | K32: 0
A33: Stockholders’ Equity
A34: Additional paid-in-capital | B34: 4982 | C34: 5061 | D34: 5298 | E34: 5893 | F34: 6442 | G34: 6442 | H34: 6442 | I34: 6442 | J34: 6442 | K34: 6442
A35: Class A treasury stock, at cost, 425 and 409 shares, respectively | B35: -36658 | C35: -42588 | D35: -51354 | E35: -60429 | F35: -71431 | G35: =Table2[[#This Row],[2024]]+('Cash Flow'!G41) -> -78083.953 | H35: =Table2[[#This Row],[2024]]+('Cash Flow'!H41) -> -77417.867 | I35: =Table2[[#This Row],[2024]]+('Cash Flow'!I41) -> -76755.905 | J35: =Table2[[#This Row],[2024]]+('Cash Flow'!J41) -> -76066.635 | K35: =Table2[[#This Row],[2024]]+('Cash Flow'!K41) -> -75360.363
A36: Retained earnings | B36: 38747 | C36: 45648 | D36: 53607 | E36: 62564 | F36: 72907 | G36: =Table2[[#This Row],[2024]]+'Profit Loss'!G20+'Cash Flow'!G42 -> 83131.777 | H36: =Table2[[#This Row],[2024]]+'Profit Loss'!H20+'Cash Flow'!H42 -> 84685.978 | I36: =Table2[[#This Row],[2024]]+'Profit Loss'!I20+'Cash Flow'!I42 -> 86230.556 | J36: =Table2[[#This Row],[2024]]+'Profit Loss'!J20+'Cash Flow'!J42 -> 87838.853 | K36: =Table2[[#This Row],[2024]]+'Profit Loss'!K20+'Cash Flow'!K42 -> 89486.819
A37: Accumulated other comprehensive income (loss) | B37: -680 | C37: -809 | D37: -1253 | E37: -1099 | F37: -1433 | G37: -1433 | H37: -1433 | I37: -1433 | J37: -1433 | K37: -1433
A38: Mastercard Incorporated Stockholders' Equity | B38: 6391 | C38: 7312 | D38: 6298 | E38: 6929 | F38: 6485 | G38: =G34+G36+G35+G37 -> 10056.825 | H38: =H34+H36+H35+H37 -> 12277.111 | I38: =I34+I36+I35+I37 -> 14483.651 | J38: =J34+J36+J35+J37 -> 16781.218 | K38: =K34+K36+K35+K37 -> 19135.455
A39: Non-controlling interests | B39: 97 | C39: 71 | D39: 58 | E39: 46 | F39: 30 | G39: 30 | H39: 30 | I39: 30 | J39: 30 | K39: 30
A40: Total Equity | B40: =B38+B39 -> 6488 | C40: =C38+C39 -> 7383 | D40: =D38+D39 -> 6356 | E40: =E38+E39 -> 6975 | F40: =F38+F39 -> 6515 | G40: =G38+G39 -> 10086.825 | H40: =H38+H39 -> 12307.111 | I40: =I38+I39 -> 14513.651 | ... K40: =K38+K39 -> 19165.455
...

Sheet Cash Flow
A1: Consolidated Statement of Cash Flows - USD ($) $ in Millions | B1: 2020 | C1: 2021 | D1: 2022 | E1: 2023 | F1: 2024 | G1: 2025E | H1: 2026E | I1: 2027E | J1: 2028E | K1: 2029E
A2: Mastercard Inc | M2: 2020-2024 | N2: Historicals
A3: Operating Activities | M3: 2025-2029 | N3: Projections
A4: Net income | B4: 6411 | C4: 8687 | D4: 9930 | E4: 11195 | F4: 12874 | G4: ='Profit Loss'!G20 -> 14606.825 | H4: ='Profit Loss'!H20 -> 16827.111 | I4: ='Profit Loss'!I20 -> 19033.651 | J4: ='Profit Loss'!J20 -> 21331.218 | K4: ='Profit Loss'!K20 -> 23685.455
A5: Adjustments to reconcile net income to net cash provided by operating activities:
A6: Amortization of customer and merchant incentives | B6: 1072 | C6: 1371 | D6: 1586 | E6: 1622 | F6: 1830 | G6: =Table3[[#This Row],[2024]]*1.05 -> 1921.5 | H6: =Table3[[#This Row],[2025E]]*1.05 -> 2017.575 | I6: =Table3[[#This Row],[2026E]]*1.05 -> 2118.4538 | J6: =Table3[[#This Row],[2027E]]*1.05 -> 2224.3764 | K6: =Table3[[#This Row],[2028E]]*1.05 -> 2335.5953
A7: Depreciation and amortization | B7: 580 | C7: 726 | D7: 750 | E7: 799 | F7: 897 | G7: ='Profit Loss'!G8 -> 946.4112 | H7: ='Profit Loss'!H8 -> 1033.7965 | I7: ='Profit Loss'!I8 -> 1117.9261 | J7: ='Profit Loss'!J8 -> 1196.5802 | K7: ='Profit Loss'!K8 -> 1267.4887
A8: (Gains) losses on equity investments, net | B8: -30 | C8: -645 | D8: 145 | E8: 61 | F8: 29 | G8: 29 | H8: 29 | I8: 29 | J8: 29 | K8: 29
A9: Share-based compensation | B9: 254 | C9: 273 | D9: 295 | E9: 460 | F9: 526 | G9: =Table3[[#This Row],[2024]]*1.06 -> 557.56 | H9: =Table3[[#This Row],[2025E]]*1.06 -> 591.0136 | I9: =Table3[[#This Row],[2026E]]*1.06 -> 626.47442 | J9: =Table3[[#This Row],[2027E]]*1.06 -> 664.06288 | K9: =Table3[[#This Row],[2028E]]*1.06 -> 703.90665
A10: Deferred income taxes | B10: 73 | C10: -69 | D10: -651 | E10: -236 | F10: -527 | G10: =Table3[[#This Row],[2024]]*1.03 -> -542.81 | H10: =Table3[[#This Row],[2025E]]*1.03 -> -559.0943 | I10: =Table3[[#This Row],[2026E]]*1.03 -> -575.86713 | J10: =Table3[[#This Row],[2027E]]*1.03 -> -593.14314 | K10: =Table3[[#This Row],[2028E]]*1.03 -> -610.93744
A11: Other | B11: 14 | C11: 36 | D11: 44 | E11: 22 | F11: 191 | G11: =Table3[[#This Row],[2024]]*1.03 -> 196.73 | H11: =Table3[[#This Row],[2025E]]*1.03 -> 202.6319 | I11: =Table3[[#This Row],[2026E]]*1.03 -> 208.71086 | J11: =Table3[[#This Row],[2027E]]*1.03 -> 214.97218 | K11: =Table3[[#This Row],[2028E]]*1.03 -> 221.42135
A12: Changes in operating assets and liabilities:
